[2024-01-13T20:23:39.738+0000] {taskinstance.py:1957} INFO - Dependencies all met for dep_context=non-requeueable deps ti=<TaskInstance: youtube_likes_score.test_model manual__2024-01-13T20:18:23.108211+00:00 [queued]>
[2024-01-13T20:23:39.745+0000] {taskinstance.py:1957} INFO - Dependencies all met for dep_context=requeueable deps ti=<TaskInstance: youtube_likes_score.test_model manual__2024-01-13T20:18:23.108211+00:00 [queued]>
[2024-01-13T20:23:39.745+0000] {taskinstance.py:2171} INFO - Starting attempt 1 of 2
[2024-01-13T20:23:39.762+0000] {taskinstance.py:2192} INFO - Executing <Task(BashOperator): test_model> on 2024-01-13 20:18:23.108211+00:00
[2024-01-13T20:23:39.763+0000] {standard_task_runner.py:60} INFO - Started process 190033 to run task
[2024-01-13T20:23:39.768+0000] {standard_task_runner.py:87} INFO - Running: ['***', 'tasks', 'run', 'youtube_likes_score', 'test_model', 'manual__2024-01-13T20:18:23.108211+00:00', '--job-id', '18', '--raw', '--subdir', 'DAGS_FOLDER/youtube_likes_score.py', '--cfg-path', '/tmp/tmpedq8xi6w']
[2024-01-13T20:23:39.770+0000] {standard_task_runner.py:88} INFO - Job 18: Subtask test_model
[2024-01-13T20:23:39.852+0000] {task_command.py:423} INFO - Running <TaskInstance: youtube_likes_score.test_model manual__2024-01-13T20:18:23.108211+00:00 [running]> on host prodsrv
[2024-01-13T20:23:39.970+0000] {taskinstance.py:2481} INFO - Exporting env vars: AIRFLOW_CTX_DAG_OWNER='admin' AIRFLOW_CTX_DAG_ID='youtube_likes_score' AIRFLOW_CTX_TASK_ID='test_model' AIRFLOW_CTX_EXECUTION_DATE='2024-01-13T20:18:23.108211+00:00' AIRFLOW_CTX_TRY_NUMBER='1' AIRFLOW_CTX_DAG_RUN_ID='manual__2024-01-13T20:18:23.108211+00:00'
[2024-01-13T20:23:39.971+0000] {subprocess.py:63} INFO - Tmp dir root location: /tmp
[2024-01-13T20:23:39.971+0000] {subprocess.py:75} INFO - Running command: ['/usr/bin/bash', '-c', "python3 /home/admin/scripts/test_model.py '/home/admin'"]
[2024-01-13T20:23:39.977+0000] {subprocess.py:86} INFO - Output:
[2024-01-13T20:23:40.697+0000] {subprocess.py:93} INFO - Traceback (most recent call last):
[2024-01-13T20:23:40.698+0000] {subprocess.py:93} INFO -   File "/home/admin/scripts/test_model.py", line 18, in <module>
[2024-01-13T20:23:40.698+0000] {subprocess.py:93} INFO -     df = pd.read_csv(test_data_file_path, header=None)
[2024-01-13T20:23:40.698+0000] {subprocess.py:93} INFO -   File "/home/admin/***/***_venv/lib/python3.10/site-packages/pandas/io/parsers/readers.py", line 948, in read_csv
[2024-01-13T20:23:40.699+0000] {subprocess.py:93} INFO -     return _read(filepath_or_buffer, kwds)
[2024-01-13T20:23:40.699+0000] {subprocess.py:93} INFO -   File "/home/admin/***/***_venv/lib/python3.10/site-packages/pandas/io/parsers/readers.py", line 611, in _read
[2024-01-13T20:23:40.699+0000] {subprocess.py:93} INFO -     parser = TextFileReader(filepath_or_buffer, **kwds)
[2024-01-13T20:23:40.699+0000] {subprocess.py:93} INFO -   File "/home/admin/***/***_venv/lib/python3.10/site-packages/pandas/io/parsers/readers.py", line 1448, in __init__
[2024-01-13T20:23:40.699+0000] {subprocess.py:93} INFO -     self._engine = self._make_engine(f, self.engine)
[2024-01-13T20:23:40.699+0000] {subprocess.py:93} INFO -   File "/home/admin/***/***_venv/lib/python3.10/site-packages/pandas/io/parsers/readers.py", line 1723, in _make_engine
[2024-01-13T20:23:40.700+0000] {subprocess.py:93} INFO -     return mapping[engine](f, **self.options)
[2024-01-13T20:23:40.700+0000] {subprocess.py:93} INFO -   File "/home/admin/***/***_venv/lib/python3.10/site-packages/pandas/io/parsers/c_parser_wrapper.py", line 93, in __init__
[2024-01-13T20:23:40.700+0000] {subprocess.py:93} INFO -     self._reader = parsers.TextReader(src, **kwds)
[2024-01-13T20:23:40.701+0000] {subprocess.py:93} INFO -   File "parsers.pyx", line 586, in pandas._libs.parsers.TextReader.__cinit__
[2024-01-13T20:23:40.701+0000] {subprocess.py:93} INFO - pandas.errors.EmptyDataError: No columns to parse from file
[2024-01-13T20:23:40.806+0000] {subprocess.py:97} INFO - Command exited with return code 1
[2024-01-13T20:23:40.829+0000] {taskinstance.py:2699} ERROR - Task failed with exception
Traceback (most recent call last):
  File "/home/admin/airflow/airflow_venv/lib/python3.10/site-packages/airflow/models/taskinstance.py", line 433, in _execute_task
    result = execute_callable(context=context, **execute_callable_kwargs)
  File "/home/admin/airflow/airflow_venv/lib/python3.10/site-packages/airflow/operators/bash.py", line 212, in execute
    raise AirflowException(
airflow.exceptions.AirflowException: Bash command failed. The command returned a non-zero exit code 1.
[2024-01-13T20:23:40.832+0000] {taskinstance.py:1138} INFO - Marking task as UP_FOR_RETRY. dag_id=youtube_likes_score, task_id=test_model, execution_date=20240113T201823, start_date=20240113T202339, end_date=20240113T202340
[2024-01-13T20:23:40.848+0000] {standard_task_runner.py:107} ERROR - Failed to execute job 18 for task test_model (Bash command failed. The command returned a non-zero exit code 1.; 190033)
[2024-01-13T20:23:40.854+0000] {local_task_job_runner.py:234} INFO - Task exited with return code 1
[2024-01-13T20:23:40.882+0000] {taskinstance.py:3281} INFO - 0 downstream tasks scheduled from follow-on schedule check
