[2024-01-13T19:40:05.360+0000] {taskinstance.py:1957} INFO - Dependencies all met for dep_context=non-requeueable deps ti=<TaskInstance: youtube_likes_score.get_data manual__2024-01-13T19:40:02.969071+00:00 [queued]>
[2024-01-13T19:40:05.366+0000] {taskinstance.py:1957} INFO - Dependencies all met for dep_context=requeueable deps ti=<TaskInstance: youtube_likes_score.get_data manual__2024-01-13T19:40:02.969071+00:00 [queued]>
[2024-01-13T19:40:05.366+0000] {taskinstance.py:2171} INFO - Starting attempt 1 of 2
[2024-01-13T19:40:05.382+0000] {taskinstance.py:2192} INFO - Executing <Task(BashOperator): get_data> on 2024-01-13 19:40:02.969071+00:00
[2024-01-13T19:40:05.383+0000] {standard_task_runner.py:60} INFO - Started process 189034 to run task
[2024-01-13T19:40:05.389+0000] {standard_task_runner.py:87} INFO - Running: ['***', 'tasks', 'run', 'youtube_likes_score', 'get_data', 'manual__2024-01-13T19:40:02.969071+00:00', '--job-id', '4', '--raw', '--subdir', 'DAGS_FOLDER/youtube_comments_score.py', '--cfg-path', '/tmp/tmp_wl46d5j']
[2024-01-13T19:40:05.390+0000] {standard_task_runner.py:88} INFO - Job 4: Subtask get_data
[2024-01-13T19:40:05.472+0000] {task_command.py:423} INFO - Running <TaskInstance: youtube_likes_score.get_data manual__2024-01-13T19:40:02.969071+00:00 [running]> on host prodsrv
[2024-01-13T19:40:05.591+0000] {taskinstance.py:2481} INFO - Exporting env vars: AIRFLOW_CTX_DAG_OWNER='admin' AIRFLOW_CTX_DAG_ID='youtube_likes_score' AIRFLOW_CTX_TASK_ID='get_data' AIRFLOW_CTX_EXECUTION_DATE='2024-01-13T19:40:02.969071+00:00' AIRFLOW_CTX_TRY_NUMBER='1' AIRFLOW_CTX_DAG_RUN_ID='manual__2024-01-13T19:40:02.969071+00:00'
[2024-01-13T19:40:05.592+0000] {subprocess.py:63} INFO - Tmp dir root location: /tmp
[2024-01-13T19:40:05.592+0000] {subprocess.py:75} INFO - Running command: ['/usr/bin/bash', '-c', 'python3 /home/scripts/get_data.py']
[2024-01-13T19:40:05.599+0000] {subprocess.py:86} INFO - Output:
[2024-01-13T19:40:05.612+0000] {subprocess.py:93} INFO - python3: can't open file '/home/scripts/get_data.py': [Errno 2] No such file or directory
[2024-01-13T19:40:05.615+0000] {subprocess.py:97} INFO - Command exited with return code 2
[2024-01-13T19:40:05.638+0000] {taskinstance.py:2699} ERROR - Task failed with exception
Traceback (most recent call last):
  File "/home/admin/airflow/airflow_venv/lib/python3.10/site-packages/airflow/models/taskinstance.py", line 433, in _execute_task
    result = execute_callable(context=context, **execute_callable_kwargs)
  File "/home/admin/airflow/airflow_venv/lib/python3.10/site-packages/airflow/operators/bash.py", line 212, in execute
    raise AirflowException(
airflow.exceptions.AirflowException: Bash command failed. The command returned a non-zero exit code 2.
[2024-01-13T19:40:05.645+0000] {taskinstance.py:1138} INFO - Marking task as UP_FOR_RETRY. dag_id=youtube_likes_score, task_id=get_data, execution_date=20240113T194002, start_date=20240113T194005, end_date=20240113T194005
[2024-01-13T19:40:05.661+0000] {standard_task_runner.py:107} ERROR - Failed to execute job 4 for task get_data (Bash command failed. The command returned a non-zero exit code 2.; 189034)
[2024-01-13T19:40:05.667+0000] {local_task_job_runner.py:234} INFO - Task exited with return code 1
[2024-01-13T19:40:05.702+0000] {taskinstance.py:3281} INFO - 0 downstream tasks scheduled from follow-on schedule check
