[2024-01-13T20:21:59.093+0000] {taskinstance.py:1957} INFO - Dependencies all met for dep_context=non-requeueable deps ti=<TaskInstance: youtube_likes_score.process_data manual__2024-01-13T20:16:50.897592+00:00 [queued]>
[2024-01-13T20:21:59.100+0000] {taskinstance.py:1957} INFO - Dependencies all met for dep_context=requeueable deps ti=<TaskInstance: youtube_likes_score.process_data manual__2024-01-13T20:16:50.897592+00:00 [queued]>
[2024-01-13T20:21:59.100+0000] {taskinstance.py:2171} INFO - Starting attempt 1 of 2
[2024-01-13T20:21:59.115+0000] {taskinstance.py:2192} INFO - Executing <Task(BashOperator): process_data> on 2024-01-13 20:16:50.897592+00:00
[2024-01-13T20:21:59.117+0000] {standard_task_runner.py:60} INFO - Started process 189916 to run task
[2024-01-13T20:21:59.122+0000] {standard_task_runner.py:87} INFO - Running: ['***', 'tasks', 'run', 'youtube_likes_score', 'process_data', 'manual__2024-01-13T20:16:50.897592+00:00', '--job-id', '13', '--raw', '--subdir', 'DAGS_FOLDER/youtube_likes_score.py', '--cfg-path', '/tmp/tmputjq2asm']
[2024-01-13T20:21:59.124+0000] {standard_task_runner.py:88} INFO - Job 13: Subtask process_data
[2024-01-13T20:21:59.208+0000] {task_command.py:423} INFO - Running <TaskInstance: youtube_likes_score.process_data manual__2024-01-13T20:16:50.897592+00:00 [running]> on host prodsrv
[2024-01-13T20:21:59.329+0000] {taskinstance.py:2481} INFO - Exporting env vars: AIRFLOW_CTX_DAG_OWNER='admin' AIRFLOW_CTX_DAG_ID='youtube_likes_score' AIRFLOW_CTX_TASK_ID='process_data' AIRFLOW_CTX_EXECUTION_DATE='2024-01-13T20:16:50.897592+00:00' AIRFLOW_CTX_TRY_NUMBER='1' AIRFLOW_CTX_DAG_RUN_ID='manual__2024-01-13T20:16:50.897592+00:00'
[2024-01-13T20:21:59.330+0000] {subprocess.py:63} INFO - Tmp dir root location: /tmp
[2024-01-13T20:21:59.330+0000] {subprocess.py:75} INFO - Running command: ['/usr/bin/bash', '-c', "python3 /home/admin/scripts/process_data.py '/home/admin'"]
[2024-01-13T20:21:59.337+0000] {subprocess.py:86} INFO - Output:
[2024-01-13T20:21:59.696+0000] {subprocess.py:93} INFO - Traceback (most recent call last):
[2024-01-13T20:21:59.696+0000] {subprocess.py:93} INFO -   File "/home/admin/scripts/process_data.py", line 10, in <module>
[2024-01-13T20:21:59.697+0000] {subprocess.py:93} INFO -     df = pd.read_csv(raw_data_file_path, header=None)
[2024-01-13T20:21:59.697+0000] {subprocess.py:93} INFO -   File "/home/admin/***/***_venv/lib/python3.10/site-packages/pandas/io/parsers/readers.py", line 948, in read_csv
[2024-01-13T20:21:59.698+0000] {subprocess.py:93} INFO -     return _read(filepath_or_buffer, kwds)
[2024-01-13T20:21:59.698+0000] {subprocess.py:93} INFO -   File "/home/admin/***/***_venv/lib/python3.10/site-packages/pandas/io/parsers/readers.py", line 611, in _read
[2024-01-13T20:21:59.698+0000] {subprocess.py:93} INFO -     parser = TextFileReader(filepath_or_buffer, **kwds)
[2024-01-13T20:21:59.698+0000] {subprocess.py:93} INFO -   File "/home/admin/***/***_venv/lib/python3.10/site-packages/pandas/io/parsers/readers.py", line 1448, in __init__
[2024-01-13T20:21:59.699+0000] {subprocess.py:93} INFO -     self._engine = self._make_engine(f, self.engine)
[2024-01-13T20:21:59.699+0000] {subprocess.py:93} INFO -   File "/home/admin/***/***_venv/lib/python3.10/site-packages/pandas/io/parsers/readers.py", line 1705, in _make_engine
[2024-01-13T20:21:59.699+0000] {subprocess.py:93} INFO -     self.handles = get_handle(
[2024-01-13T20:21:59.699+0000] {subprocess.py:93} INFO -   File "/home/admin/***/***_venv/lib/python3.10/site-packages/pandas/io/common.py", line 863, in get_handle
[2024-01-13T20:21:59.700+0000] {subprocess.py:93} INFO -     handle = open(
[2024-01-13T20:21:59.700+0000] {subprocess.py:93} INFO - FileNotFoundError: [Errno 2] No such file or directory: '/tmp/data/raw_data.csv'
[2024-01-13T20:21:59.752+0000] {subprocess.py:97} INFO - Command exited with return code 1
[2024-01-13T20:21:59.774+0000] {taskinstance.py:2699} ERROR - Task failed with exception
Traceback (most recent call last):
  File "/home/admin/airflow/airflow_venv/lib/python3.10/site-packages/airflow/models/taskinstance.py", line 433, in _execute_task
    result = execute_callable(context=context, **execute_callable_kwargs)
  File "/home/admin/airflow/airflow_venv/lib/python3.10/site-packages/airflow/operators/bash.py", line 212, in execute
    raise AirflowException(
airflow.exceptions.AirflowException: Bash command failed. The command returned a non-zero exit code 1.
[2024-01-13T20:21:59.778+0000] {taskinstance.py:1138} INFO - Marking task as UP_FOR_RETRY. dag_id=youtube_likes_score, task_id=process_data, execution_date=20240113T201650, start_date=20240113T202159, end_date=20240113T202159
[2024-01-13T20:21:59.794+0000] {standard_task_runner.py:107} ERROR - Failed to execute job 13 for task process_data (Bash command failed. The command returned a non-zero exit code 1.; 189916)
[2024-01-13T20:21:59.829+0000] {local_task_job_runner.py:234} INFO - Task exited with return code 1
[2024-01-13T20:21:59.865+0000] {taskinstance.py:3281} INFO - 0 downstream tasks scheduled from follow-on schedule check
